[2023-09-02T21:57:25.516+0000] {taskinstance.py:1083} INFO - Dependencies all met for <TaskInstance: dagemail.tsk4 manual__2023-09-02T21:57:02.065002+00:00 [queued]>
[2023-09-02T21:57:25.527+0000] {taskinstance.py:1083} INFO - Dependencies all met for <TaskInstance: dagemail.tsk4 manual__2023-09-02T21:57:02.065002+00:00 [queued]>
[2023-09-02T21:57:25.528+0000] {taskinstance.py:1279} INFO - 
--------------------------------------------------------------------------------
[2023-09-02T21:57:25.528+0000] {taskinstance.py:1280} INFO - Starting attempt 2 of 2
[2023-09-02T21:57:25.528+0000] {taskinstance.py:1281} INFO - 
--------------------------------------------------------------------------------
[2023-09-02T21:57:25.544+0000] {taskinstance.py:1300} INFO - Executing <Task(BashOperator): tsk4> on 2023-09-02 21:57:02.065002+00:00
[2023-09-02T21:57:25.550+0000] {standard_task_runner.py:55} INFO - Started process 1133 to run task
[2023-09-02T21:57:25.553+0000] {standard_task_runner.py:82} INFO - Running: ['***', 'tasks', 'run', 'dagemail', 'tsk4', 'manual__2023-09-02T21:57:02.065002+00:00', '--job-id', '246', '--raw', '--subdir', 'DAGS_FOLDER/dagemail.py', '--cfg-path', '/tmp/tmp740jx73w']
[2023-09-02T21:57:25.554+0000] {standard_task_runner.py:83} INFO - Job 246: Subtask tsk4
[2023-09-02T21:57:25.629+0000] {task_command.py:388} INFO - Running <TaskInstance: dagemail.tsk4 manual__2023-09-02T21:57:02.065002+00:00 [running]> on host 8d5456a88302
[2023-09-02T21:57:25.702+0000] {taskinstance.py:1509} INFO - Exporting the following env vars:
AIRFLOW_CTX_DAG_EMAIL=tiagolinhares051@gmail.com
AIRFLOW_CTX_DAG_OWNER=***
AIRFLOW_CTX_DAG_ID=dagemail
AIRFLOW_CTX_TASK_ID=tsk4
AIRFLOW_CTX_EXECUTION_DATE=2023-09-02T21:57:02.065002+00:00
AIRFLOW_CTX_TRY_NUMBER=2
AIRFLOW_CTX_DAG_RUN_ID=manual__2023-09-02T21:57:02.065002+00:00
[2023-09-02T21:57:25.703+0000] {subprocess.py:63} INFO - Tmp dir root location: 
 /tmp
[2023-09-02T21:57:25.704+0000] {subprocess.py:75} INFO - Running command: ['/bin/bash', '-c', 'exit 1']
[2023-09-02T21:57:25.715+0000] {subprocess.py:86} INFO - Output:
[2023-09-02T21:57:25.718+0000] {subprocess.py:97} INFO - Command exited with return code 1
[2023-09-02T21:57:25.728+0000] {taskinstance.py:1768} ERROR - Task failed with exception
Traceback (most recent call last):
  File "/home/airflow/.local/lib/python3.7/site-packages/airflow/operators/bash.py", line 197, in execute
    f"Bash command failed. The command returned a non-zero exit code {result.exit_code}."
airflow.exceptions.AirflowException: Bash command failed. The command returned a non-zero exit code 1.
[2023-09-02T21:57:25.732+0000] {taskinstance.py:1323} INFO - Marking task as FAILED. dag_id=dagemail, task_id=tsk4, execution_date=20230902T215702, start_date=20230902T215725, end_date=20230902T215725
[2023-09-02T21:57:25.750+0000] {warnings.py:110} WARNING - /home/***/.local/lib/python3.7/site-packages/***/utils/email.py:152: RemovedInAirflow3Warning: Fetching SMTP credentials from configuration variables will be deprecated in a future release. Please set credentials using a connection instead.
  send_mime_email(e_from=mail_from, e_to=recipients, mime_msg=msg, conn_id=conn_id, dryrun=dryrun)

[2023-09-02T21:57:25.750+0000] {configuration.py:663} WARNING - section/key [smtp/smtp_user] not found in config
[2023-09-02T21:57:25.750+0000] {email.py:268} INFO - Email alerting: attempt 1
[2023-09-02T21:57:27.452+0000] {email.py:280} INFO - Sent an alert email to ['tiagolinhares051@gmail.com']
[2023-09-02T21:57:28.038+0000] {configuration.py:663} WARNING - section/key [smtp/smtp_user] not found in config
[2023-09-02T21:57:28.038+0000] {email.py:268} INFO - Email alerting: attempt 1
[2023-09-02T21:57:29.562+0000] {email.py:280} INFO - Sent an alert email to ['tiagolinhares051@gmail.com']
[2023-09-02T21:57:30.222+0000] {taskinstance.py:1831} ERROR - Failed to send email to: ['tiagolinhares051@gmail.com']
Traceback (most recent call last):
  File "/home/airflow/.local/lib/python3.7/site-packages/airflow/models/taskinstance.py", line 1374, in _run_raw_task
    self._execute_task_with_callbacks(context, test_mode)
  File "/home/airflow/.local/lib/python3.7/site-packages/airflow/models/taskinstance.py", line 1520, in _execute_task_with_callbacks
    result = self._execute_task(context, task_orig)
  File "/home/airflow/.local/lib/python3.7/site-packages/airflow/models/taskinstance.py", line 1581, in _execute_task
    result = execute_callable(context=context)
  File "/home/airflow/.local/lib/python3.7/site-packages/airflow/operators/bash.py", line 197, in execute
    f"Bash command failed. The command returned a non-zero exit code {result.exit_code}."
airflow.exceptions.AirflowException: Bash command failed. The command returned a non-zero exit code 1.

During handling of the above exception, another exception occurred:

Traceback (most recent call last):
  File "/home/airflow/.local/lib/python3.7/site-packages/airflow/models/taskinstance.py", line 2231, in email_alert
    send_email(task.email, subject, html_content)
  File "/home/airflow/.local/lib/python3.7/site-packages/airflow/utils/email.py", line 91, in send_email
    **kwargs,
  File "/home/airflow/.local/lib/python3.7/site-packages/airflow/utils/email.py", line 152, in send_email_smtp
    send_mime_email(e_from=mail_from, e_to=recipients, mime_msg=msg, conn_id=conn_id, dryrun=dryrun)
  File "/home/airflow/.local/lib/python3.7/site-packages/airflow/utils/email.py", line 281, in send_mime_email
    smtp_conn.sendmail(e_from, e_to, mime_msg.as_string())
  File "/usr/local/lib/python3.7/smtplib.py", line 872, in sendmail
    raise SMTPSenderRefused(code, resp, from_addr)
smtplib.SMTPSenderRefused: (530, b'5.7.0 Authentication Required. Learn more at\n5.7.0  https://support.google.com/mail/?p=WantAuthError s42-20020a05680820aa00b003a84c946bd1sm3417601oiw.55 - gsmtp', '***')

During handling of the above exception, another exception occurred:

Traceback (most recent call last):
  File "/home/airflow/.local/lib/python3.7/site-packages/airflow/models/taskinstance.py", line 1829, in handle_failure
    self.email_alert(error, task)
  File "/home/airflow/.local/lib/python3.7/site-packages/airflow/models/taskinstance.py", line 2233, in email_alert
    send_email(task.email, subject, html_content_err)
  File "/home/airflow/.local/lib/python3.7/site-packages/airflow/utils/email.py", line 91, in send_email
    **kwargs,
  File "/home/airflow/.local/lib/python3.7/site-packages/airflow/utils/email.py", line 152, in send_email_smtp
    send_mime_email(e_from=mail_from, e_to=recipients, mime_msg=msg, conn_id=conn_id, dryrun=dryrun)
  File "/home/airflow/.local/lib/python3.7/site-packages/airflow/utils/email.py", line 281, in send_mime_email
    smtp_conn.sendmail(e_from, e_to, mime_msg.as_string())
  File "/usr/local/lib/python3.7/smtplib.py", line 872, in sendmail
    raise SMTPSenderRefused(code, resp, from_addr)
smtplib.SMTPSenderRefused: (530, b'5.7.0 Authentication Required. Learn more at\n5.7.0  https://support.google.com/mail/?p=WantAuthError v21-20020a05683011d500b006b8c277be12sm3167883otq.8 - gsmtp', '***')
[2023-09-02T21:57:30.235+0000] {standard_task_runner.py:105} ERROR - Failed to execute job 246 for task tsk4 (Bash command failed. The command returned a non-zero exit code 1.; 1133)
[2023-09-02T21:57:30.261+0000] {local_task_job.py:208} INFO - Task exited with return code 1
[2023-09-02T21:57:30.284+0000] {taskinstance.py:2578} INFO - 0 downstream tasks scheduled from follow-on schedule check
