[2023-09-02T22:09:15.105+0000] {taskinstance.py:1083} INFO - Dependencies all met for <TaskInstance: dagemail.sendemail manual__2023-09-02T22:08:32.762713+00:00 [queued]>
[2023-09-02T22:09:15.125+0000] {taskinstance.py:1083} INFO - Dependencies all met for <TaskInstance: dagemail.sendemail manual__2023-09-02T22:08:32.762713+00:00 [queued]>
[2023-09-02T22:09:15.126+0000] {taskinstance.py:1279} INFO - 
--------------------------------------------------------------------------------
[2023-09-02T22:09:15.126+0000] {taskinstance.py:1280} INFO - Starting attempt 2 of 2
[2023-09-02T22:09:15.126+0000] {taskinstance.py:1281} INFO - 
--------------------------------------------------------------------------------
[2023-09-02T22:09:15.159+0000] {taskinstance.py:1300} INFO - Executing <Task(EmailOperator): sendemail> on 2023-09-02 22:08:32.762713+00:00
[2023-09-02T22:09:15.170+0000] {standard_task_runner.py:55} INFO - Started process 1867 to run task
[2023-09-02T22:09:15.175+0000] {standard_task_runner.py:82} INFO - Running: ['***', 'tasks', 'run', 'dagemail', 'sendemail', 'manual__2023-09-02T22:08:32.762713+00:00', '--job-id', '253', '--raw', '--subdir', 'DAGS_FOLDER/dagemail.py', '--cfg-path', '/tmp/tmpbgwi14dh']
[2023-09-02T22:09:15.176+0000] {standard_task_runner.py:83} INFO - Job 253: Subtask sendemail
[2023-09-02T22:09:15.281+0000] {task_command.py:388} INFO - Running <TaskInstance: dagemail.sendemail manual__2023-09-02T22:08:32.762713+00:00 [running]> on host 8d5456a88302
[2023-09-02T22:09:15.371+0000] {taskinstance.py:1509} INFO - Exporting the following env vars:
AIRFLOW_CTX_DAG_EMAIL=eternoaprendiz015@gmail.com
AIRFLOW_CTX_DAG_OWNER=***
AIRFLOW_CTX_DAG_ID=dagemail
AIRFLOW_CTX_TASK_ID=sendemail
AIRFLOW_CTX_EXECUTION_DATE=2023-09-02T22:08:32.762713+00:00
AIRFLOW_CTX_TRY_NUMBER=2
AIRFLOW_CTX_DAG_RUN_ID=manual__2023-09-02T22:08:32.762713+00:00
[2023-09-02T22:09:15.385+0000] {warnings.py:110} WARNING - /home/***/.local/lib/python3.7/site-packages/***/utils/email.py:152: RemovedInAirflow3Warning: Fetching SMTP credentials from configuration variables will be deprecated in a future release. Please set credentials using a connection instead.
  send_mime_email(e_from=mail_from, e_to=recipients, mime_msg=msg, conn_id=conn_id, dryrun=dryrun)

[2023-09-02T22:09:15.385+0000] {configuration.py:663} WARNING - section/key [smtp/smtp_user] not found in config
[2023-09-02T22:09:15.386+0000] {email.py:268} INFO - Email alerting: attempt 1
[2023-09-02T22:09:16.288+0000] {email.py:280} INFO - Sent an alert email to ['eternoaprendiz015@gmail.com']
[2023-09-02T22:09:16.945+0000] {taskinstance.py:1768} ERROR - Task failed with exception
Traceback (most recent call last):
  File "/home/airflow/.local/lib/python3.7/site-packages/airflow/operators/email.py", line 87, in execute
    custom_headers=self.custom_headers,
  File "/home/airflow/.local/lib/python3.7/site-packages/airflow/utils/email.py", line 91, in send_email
    **kwargs,
  File "/home/airflow/.local/lib/python3.7/site-packages/airflow/utils/email.py", line 152, in send_email_smtp
    send_mime_email(e_from=mail_from, e_to=recipients, mime_msg=msg, conn_id=conn_id, dryrun=dryrun)
  File "/home/airflow/.local/lib/python3.7/site-packages/airflow/utils/email.py", line 281, in send_mime_email
    smtp_conn.sendmail(e_from, e_to, mime_msg.as_string())
  File "/usr/local/lib/python3.7/smtplib.py", line 872, in sendmail
    raise SMTPSenderRefused(code, resp, from_addr)
smtplib.SMTPSenderRefused: (530, b'5.7.0 Authentication Required. Learn more at\n5.7.0  https://support.google.com/mail/?p=WantAuthError v4-20020a9d4e84000000b006b94a14b52asm3161929otk.9 - gsmtp', '***')
[2023-09-02T22:09:16.958+0000] {taskinstance.py:1323} INFO - Marking task as FAILED. dag_id=dagemail, task_id=sendemail, execution_date=20230902T220832, start_date=20230902T220915, end_date=20230902T220916
[2023-09-02T22:09:16.976+0000] {configuration.py:663} WARNING - section/key [smtp/smtp_user] not found in config
[2023-09-02T22:09:16.977+0000] {email.py:268} INFO - Email alerting: attempt 1
[2023-09-02T22:09:17.845+0000] {email.py:280} INFO - Sent an alert email to ['eternoaprendiz015@gmail.com']
[2023-09-02T22:09:18.475+0000] {configuration.py:663} WARNING - section/key [smtp/smtp_user] not found in config
[2023-09-02T22:09:18.475+0000] {email.py:268} INFO - Email alerting: attempt 1
[2023-09-02T22:09:19.432+0000] {email.py:280} INFO - Sent an alert email to ['eternoaprendiz015@gmail.com']
[2023-09-02T22:09:20.102+0000] {taskinstance.py:1831} ERROR - Failed to send email to: ['eternoaprendiz015@gmail.com']
Traceback (most recent call last):
  File "/home/airflow/.local/lib/python3.7/site-packages/airflow/models/taskinstance.py", line 1374, in _run_raw_task
    self._execute_task_with_callbacks(context, test_mode)
  File "/home/airflow/.local/lib/python3.7/site-packages/airflow/models/taskinstance.py", line 1520, in _execute_task_with_callbacks
    result = self._execute_task(context, task_orig)
  File "/home/airflow/.local/lib/python3.7/site-packages/airflow/models/taskinstance.py", line 1581, in _execute_task
    result = execute_callable(context=context)
  File "/home/airflow/.local/lib/python3.7/site-packages/airflow/operators/email.py", line 87, in execute
    custom_headers=self.custom_headers,
  File "/home/airflow/.local/lib/python3.7/site-packages/airflow/utils/email.py", line 91, in send_email
    **kwargs,
  File "/home/airflow/.local/lib/python3.7/site-packages/airflow/utils/email.py", line 152, in send_email_smtp
    send_mime_email(e_from=mail_from, e_to=recipients, mime_msg=msg, conn_id=conn_id, dryrun=dryrun)
  File "/home/airflow/.local/lib/python3.7/site-packages/airflow/utils/email.py", line 281, in send_mime_email
    smtp_conn.sendmail(e_from, e_to, mime_msg.as_string())
  File "/usr/local/lib/python3.7/smtplib.py", line 872, in sendmail
    raise SMTPSenderRefused(code, resp, from_addr)
smtplib.SMTPSenderRefused: (530, b'5.7.0 Authentication Required. Learn more at\n5.7.0  https://support.google.com/mail/?p=WantAuthError v4-20020a9d4e84000000b006b94a14b52asm3161929otk.9 - gsmtp', '***')

During handling of the above exception, another exception occurred:

Traceback (most recent call last):
  File "/home/airflow/.local/lib/python3.7/site-packages/airflow/models/taskinstance.py", line 2231, in email_alert
    send_email(task.email, subject, html_content)
  File "/home/airflow/.local/lib/python3.7/site-packages/airflow/utils/email.py", line 91, in send_email
    **kwargs,
  File "/home/airflow/.local/lib/python3.7/site-packages/airflow/utils/email.py", line 152, in send_email_smtp
    send_mime_email(e_from=mail_from, e_to=recipients, mime_msg=msg, conn_id=conn_id, dryrun=dryrun)
  File "/home/airflow/.local/lib/python3.7/site-packages/airflow/utils/email.py", line 281, in send_mime_email
    smtp_conn.sendmail(e_from, e_to, mime_msg.as_string())
  File "/usr/local/lib/python3.7/smtplib.py", line 872, in sendmail
    raise SMTPSenderRefused(code, resp, from_addr)
smtplib.SMTPSenderRefused: (530, b'5.7.0 Authentication Required. Learn more at\n5.7.0  https://support.google.com/mail/?p=WantAuthError e19-20020a056808149300b003a5b027ccb2sm3452258oiw.38 - gsmtp', '***')

During handling of the above exception, another exception occurred:

Traceback (most recent call last):
  File "/home/airflow/.local/lib/python3.7/site-packages/airflow/models/taskinstance.py", line 1829, in handle_failure
    self.email_alert(error, task)
  File "/home/airflow/.local/lib/python3.7/site-packages/airflow/models/taskinstance.py", line 2233, in email_alert
    send_email(task.email, subject, html_content_err)
  File "/home/airflow/.local/lib/python3.7/site-packages/airflow/utils/email.py", line 91, in send_email
    **kwargs,
  File "/home/airflow/.local/lib/python3.7/site-packages/airflow/utils/email.py", line 152, in send_email_smtp
    send_mime_email(e_from=mail_from, e_to=recipients, mime_msg=msg, conn_id=conn_id, dryrun=dryrun)
  File "/home/airflow/.local/lib/python3.7/site-packages/airflow/utils/email.py", line 281, in send_mime_email
    smtp_conn.sendmail(e_from, e_to, mime_msg.as_string())
  File "/usr/local/lib/python3.7/smtplib.py", line 872, in sendmail
    raise SMTPSenderRefused(code, resp, from_addr)
smtplib.SMTPSenderRefused: (530, b'5.7.0 Authentication Required. Learn more at\n5.7.0  https://support.google.com/mail/?p=WantAuthError ed38-20020a056870b7a600b001c52b2bdb51sm3739674oab.37 - gsmtp', '***')
[2023-09-02T22:09:20.116+0000] {standard_task_runner.py:105} ERROR - Failed to execute job 253 for task sendemail ((530, b'5.7.0 Authentication Required. Learn more at\n5.7.0  https://support.google.com/mail/?p=WantAuthError v4-20020a9d4e84000000b006b94a14b52asm3161929otk.9 - gsmtp', '***'); 1867)
[2023-09-02T22:09:20.138+0000] {local_task_job.py:208} INFO - Task exited with return code 1
[2023-09-02T22:09:20.159+0000] {taskinstance.py:2578} INFO - 0 downstream tasks scheduled from follow-on schedule check
